Workbook

Sheet Matriz Check List
C3: MATRIZ PARA COMPROBACIÓN REQUERIMIENTOS DE CALIDAD DE PROYECTO ACADEMICO
D5: SISTEMA: | E5: SISTEMA DE INVENTARIO DE MATERIA PRIMA (SIMP)
B6: Requerimientos Funcionales
B7: Nº | C7: CRITERIOS DE CALIDAD (Documento/Requerimientos) | E7: Status Nivel de Acuerdo | F7: CU001.1 GESTIONAR PRODUCTOS | G7: Status Nivel de Acuerdo | H7: CU001.2 Gestionar unidades de medida | I7: Status Nivel de Acuerdo | J7: CU001.3 Gestionar categorías de inventario | K7: Status Nivel de Acuerdo | L7: CU001.4 Consolidar Inventario del Sistema | M7: Status Nivel de Acuerdo | N7: CU001.5 Gestionar compras | O7: Status Nivel de Acuerdo | P7: CU001.6 Alertar de Cantidad de Existencias Baja | Q7: Status Nivel de Acuerdo | R7: CU001.7 Consultar existencias | S7: Status Nivel de Acuerdo | T7: CU001.8 Generar Reportes de Inventario | U7: Status Nivel de Acuerdo | V7: CU001.9 Registrar estado físico del inventario | W7: Status Nivel de Acuerdo | X7: CU001.10 Registrar estado físico del inventario | Y7: Status Nivel de Acuerdo | Z7: CU001.11 Registrar Novedades de Inventario | AA7: Status Nivel de Acuerdo | AB7: CU001.12 Registrar automáticamente novedades de conteo
B9: 1 | C9: Agreed | E9: OK | F9: 1. Videoconferencia de la entrevista 2. Minuta de la entrevista 3. Aceptación por videoconferencia | G9: OK | H9: 1. Videoconferencia de la entrevista 2. Minuta de la entrevista 3. Aceptación del prototipo no funcional mediante videoconferencia | I9: OK | J9: 1. Videoconferencia de la entrevista 2. Minuta de la entrevista 3. Aceptación del prototipo no funcional mediante videoconferencia | K9: OK | L9: 1. Videoconferencia de la entrevista 2. Minuta de la entrevista 3. Aceptación del prototipo no funcional mediante videoconferencia | M9: OK | N9: 1. Videoconferencia de la entrevista 2. El requerimiento fue levantado y validado en las entrevistas con el cliente | O9: OK | P9: 1. Videoconferencia de la entrevista 2. Minuta de la entrevista 3. Aceptación del prototipo no funcional mediante videoconferencia | Q9: OK | R9: 1. Videoconferencia de la entrevista 2. Minuta de la entrevista 3. Aceptación del prototipo no funcional mediante videoconferencia | S9: OK | T9: 1. Videoconferencia de la entrevista 2. Minuta de la entrevista 3. Aceptación del prototipo no funcional mediante videoconferencia | U9: OK | V9: 1. Videoconferencia de la entrevista 2. Minuta de la entrevista 3. Aceptación del prototipo no funcional de registro de inventario mediante videoconferencia | W9: OK | X9: 1. Videoconferencia de la entrevista 2. Minuta de la entrevista 3. Aceptación del prototipo no funcional mediante videoconferencia | Y9: OK | Z9: 1. Videoconferencia de la entrevista 2. Minuta de la entrevista 3. Aceptación del prototipo no funcional mediante videoconferencia | AA9: OK | AB9: 1. Videoconferencia de la entrevista 2. Minuta de la entrevista 3. Aceptación del prototipo no funcional mediante videoconferencia
B10: 2 | C10: Ranked | E10: OK | F10: 1. En la descripción del caso de Uso se especifica la prioridad Primario | G10: OK | H10: 1. En la descripción del caso de Uso se especifica la prioridad Primario | I10: OK | J10: 1. En la descripción del caso de Uso se especifica de tipo primario | K10: OK | L10: 1. La descripción del CU indica Tipo: "Primario y crítico". 2. RF-04 tiene prioridad Alta/Esencial. | M10: OK | N10: 1. En la descripción del Caso de Uso se especifica que es de "Tipo: Primario" y el requerimiento RF-05 marca prioridad "Alta/Esencial" | O10: OK | P10: 1. RF-06 y RF-UI-4: prioridad Alta/Esencial 2. El CU lo clasifica como "Secundario y automático" (ver Consisten) | Q10: OK | R10: 1. Se especifica claramente que es un caso de uso de "Tipo: Primario" | S10: OK | T10: 1. La descripción del CU indica Tipo: "Primario y crítico". 2. RF-04 tiene prioridad Alta/Esencial. | U10: OK | V10: 1. Agrupa múltiples responsabilidades en un solo CU (usuarios, roles y auditorías), rompiendo la atomicidad. 2. Clasificado como Primario, pero requiere dividirse en CUs específicos (p. ej., Gestionar Usuarios, Gestionar Roles). | W10: OK | X10: 1. RF de control de stock y cierre de caja: prioridad Alta/Esencial. 2. Clasificado correctamente como Primario al ser la actividad clave del Cajero en cada turno. | Y10: OK | Z10: 1. RF-11 y RF-UI-3: prioridad Alta/Esencial 2. El CU lo clasifica como "Secundario" (ver Consisten) | AA10: OK | AB10: 1. RF de detección de mermas e inconsistencias: prioridad Alta. 2. Clasificado correctamente como "Secundario y automático" al ser desencadenado de forma autónoma por la aplicación.
B11: 3 | C11: Unambiguos | E11: OK | F11: 1. Redacción en lenguaje claro. 2. El tutor y el equipo interpretan de igual manera el caso de uso | G11: NOK | H11: 1. La redacción puede ser más especifica y clara | I11: OK | J11: 1. Redacción en lenguaje claro. 2. El tutor y el equipo interpretan de igual manera el caso de uso | K11: NOK | L11: 1. No se define cómo se combinan los conteos físicos y las compras para obtener las existencias, ni de dónde se derivan las "salidas" por producto. 2. No es claro si la consolidación es automática (Alcance 1.2) o la ejecuta el Administrador (actor del CU). | M11: OK | N11: 1. Redacción clara y directa. El equipo y el cliente entienden claramente que sirve para registrar y administrar el abastecimiento. | O11: NOK | P11: 1. "Alcanzado o superado el umbral" (CU) vs "iguales o inferiores al stock mínimo" (RF-UI-4) 2. "Alerta visual y/o notificación": canal y destinatario sin definir | Q11: OK | R11: 1. La redacción es clara. Se entiende perfectamente que la funcionalidad sirve para visualizar el stock actual utilizando filtros específicos (producto, categoría, fecha) | S11: NOK | T11: 1. "Tipo de reporte" sin catálogo de tipos 2. Formato "(PDF, Excel, etc.)" abierto; RF-SW-2 solo define PDF y Excel 3. "Movimientos históricos" sin definir | U11: OK | V11: 1. Redacción clara pero abarca un alcance demasiado amplio para una sola especificación. 2. El actor está bien definido (Administrador), pero las entradas no detallan campos obligatorios para perfiles y auditorías. | W11: OK | X11: 1. Redacción en lenguaje claro y delimitado a las tareas del turno. 2. Actor único definido (Cajero) y entradas enfocadas en cantidades contadas por producto y turno. | Y11: OK | Z11: 1. Redacción en lenguaje claro. 2. "Novedad" se precisa en 2.3 (mermas, pérdidas o inconsistencias) y el actor es único (Cajero) | AA11: OK | AB11: 1. Redacción clara de la regla de comparación entre conteos consecutivos. 2. Actor correctamente asignado al Sistema y salida orientada a la notificación del Administrador.
B12: 4 | C12: Valid and up-to date | E12: OK | F12: 1. Toda nueva información ha sido incorporada, se han incorporado los últimos cambios pedidos luego del feedback realizado por el cliente | G12: OK | H12: 1. Toda la información ha sido incorporada con el último feedback | I12: OK | J12: 1. Toda nueva información ha sido incorporada, se han incorporado los últimos cambios pedidos luego del feedback realizado por el cliente | K12: OK | L12: 1. Toda nueva información ha sido incorporada, se han incorporado los últimos cambios pedidos luego del feedback realizado por el cliente | M12: OK | N12: 1. La funcionalidad es válida, vigente y necesaria para la consolidación del inventario del sistema. | O12: OK | P12: 1. "Alcanzado o superado el umbral" (CU) vs "iguales o inferiores al stock mínimo" (RF-UI-4) 2. "Alerta visual y/o notificación": canal y destinatario sin definir | Q12: OK | R12: 1. Representa una necesidad vigente y fundamental del negocio para reemplazar la consulta de registros manuales y en papel. | S12: OK | T12: 1. Coincide con Alcance (1.2), Perspectiva (2.1) y RF-SW-2 2. Sin notas de cambio pendientes en el CU | U12: OK | V12: 1. Toda nueva información ha sido incorporada, se han ajustado las funciones administrativas solicitadas por el cliente en el último feedback. | W12: OK | X12: 1. Se han incorporado las modificaciones solicitadas respecto a los tres momentos de conteo (inicio, cambio y cierre de turno). | Y12: OK | Z12: 1. Toda nueva información ha sido incorporada, se han incorporado los últimos cambios pedidos luego del feedback realizado por el cliente | AA12: OK | AB12: 1. Se incorporó la regla de notificación automática al Administrador tras las observaciones del cliente.
B13: 5 | C13: Correct | E13: OK | F13: 1. Está alineado con los objetivos del sistema. 2. Refleja lo que realmente necesita el cliente. | G13: OK | H13: 1. Está alineado con los objetivos del sistema. 2. Refleja lo que realmente necesita el cliente. | I13: OK | J13: 1. Está alineado con los objetivos del sistema. 2. Refleja lo que realmente necesita el cliente. | K13: OK | L13: 1. Está alineado con el objetivo del SIMP: inventario confiable, actualizado y trazable. 2. Refleja la necesidad del cliente de reemplazar los conteos y registros manuales. | M13: OK | N13: 1. Está totalmente alineado con el objetivo central del SIMP de controlar el abastecimiento de materia prima en los locales. | O13: OK | P13: 1. Alineado con el objetivo del SIMP: apoyar las decisiones de abastecimiento (Introducción) 2. Refleja la necesidad de evitar faltantes de materia prima | Q13: OK | R13: 1. Cumple correctamente con el objetivo principal del sistema SIMP, que es dar visibilidad al estado actual de la materia prima. | S13: OK | T13: 1. Alineado con el objetivo de control y respaldo administrativo (Propósito del CU) 2. Refleja la necesidad de consolidar información de las tres sucursales | U13: OK | V13: 1. Alineado con el objetivo de control de acceso y trazabilidad del sistema. 2. Refleja la necesidad del negocio de gestionar el personal autorizado. | W13: OK | X13: 1. Alineado con el objetivo de control de stock físico vs. lógico y reducción de pérdidas. 2. Refleja la necesidad operativa diaria en el punto de venta. | Y13: OK | Z13: 1. Alineado con el objetivo de trazabilidad y reducción de errores manuales (Introducción) 2. Refleja la necesidad de registrar mermas, pérdidas e inconsistencias (2.3) | AA13: OK | AB13: 1. Alineado con el objetivo de trazabilidad, auditoría automática y detección temprana de mermas o pérdidas en inventario.
B14: 6 | C14: Consisten | E14: OK | F14: 1. Documentación basada en modelos: Diagrama de Casos de Uso 2. Usa términos definidos previamente. | G14: OK | H14: 1. Documentación basada en modelos: Diagrama de Casos de Uso 2. Usa términos definidos previamente. | I14: OK | J14: 1. Documentación basada en modelos: Diagrama de Casos de Uso 2. Usa términos definidos previamente. | K14: NOK | L14: 1. Documentación basada en modelos: Diagrama de Casos de Uso. Usa términos definidos (Stock, Inventario). 2. En el diagrama, <<include>> entre "Gestionar compras" y "Actualizar existencias" tiene el sentido invertido. 3. El diagrama no relaciona el registro de conteos físicos con la consolidación, aunque la descripción los integra. | M14: OK | N14: 1. Documentación basada en el Diagrama de Casos de Uso. Utiliza términos coherentes con el resto del documento (proveedor, administrador, inventario). | O14: NOK | P14: 1. Tipo "Secundario y automático" vs RF-06 Alta/Esencial 2. El diagrama dice "Actualizar existencias del sistema" y el CU "Consolidar inventario del sistema" | Q14: OK | R14: 1. Es coherente con el resto del sistema, compartiendo los mismos actores definidos previamente (Administrador, Cajero). | S14: OK | T14: 1. Documentación basada en modelos: Diagrama de Casos de Uso (Administrador - Generar reportes) 2. Usa términos del glosario y coincide con RF-SW-2 en PDF y Excel | U14: NOK | V14: 1. Clasificado como CU único Primario frente a requerimientos que exigen separación por niveles de seguridad y permisos distintos. | W14: OK | X14: 1. Clasificación Primaria coherente con los requisitos funcionales de la gestión de inventarios. | Y14: NOK | Z14: 1. Tipo "Secundario" vs RF-11 Alta/Esencial 2. RF-10 (estado físico) cita como fuente el CU "Registrar novedades de inventario" | AA14: OK | AB14: 1. Clasificación adecuada como subfunción/proceso automático gatillado por la ejecución del conteo físico.
B15: 7 | C15: Verificable | E15: NOK | F15: 1. Requisito Medible 2. Falta Casos de Prueba | G15: NOK | H15: 1.No ha sido desarrollado | I15: NOK | J15: 1. Requisito Medible 2. Falta Casos de Prueba 3. No ha sido desarrollado | K15: NOK | L15: 1. Las salidas se describen de forma cualitativa ("existencias actualizadas"), sin criterios de aceptación medibles. 2. Faltan casos de prueba; NF-04 (< 5 s) cubre consultas y reportes, no la consolidación. | M15: NOK | N15: 1. Requisito no medible actualmente. Faltan Criterios de Aceptación y Casos de Prueba | O15: NOK | P15: 1. Las salidas se describen de forma cualitativa ("existencias actualizadas"), sin criterios de aceptación medibles. 2. Faltan casos de prueba; NF-04 (< 5 s) cubre consultas y reportes, no la consolidación. | Q15: NOK | R15: 1. Faltan Casos de Prueba. Por ejemplo, no se define cómo se debe comportar el sistema si la consulta con filtros no arroja resultados o si falla la base de datos. | S15: NOK | T15: 1. Parcialmente medible: NF-04 (< 5 s) y RF-SW-2 (PDF/Excel con encabezados y fechas) 2. Faltan casos de prueba por tipo de reporte | U15: NOK | V15: 1. Sin criterios de aceptación medibles (no especifica reglas de contraseña, roles por defecto o persistencia de logs de auditoría). 2. Faltan casos de prueba. | W15: NOK | X15: 1. Sin criterios de aceptación medibles (falta validar que las cantidades contadas sean valores no negativos o enteros). 2. Faltan casos de prueba. | Y15: NOK | Z15: 1. Sin criterios de aceptación medibles (campos obligatorios, formato y tamaño de la evidencia) 2. Faltan casos de prueba | AA15: NOK | AB15: 1. Sin criterios de aceptación medibles (falta definir el umbral o margen de tolerancia para considerar una diferencia como "novedad"). 2. Faltan casos de prueba automatizados.
B16: 8 | C16: Realizable | E16: NOK | F16: 1. Funcionalidad tomada en cuenta dentro de la estimación del costo del proyecto 2. No se ha desarrollado | G16: NOK | H16: 1. No ha sido desarrollado | I16: NOK | J16: 1. No ha sido desarrollado | K16: NOK | L16: 1. No ha sido desarrollado | M16: NOK | N16: 1. No ha sido desarrollado | O16: NOK | P16: 1. No ha sido desarrollado | Q16: NOK | R16: 1. No ha sido desarrollado | S16: NOK | T16: 1. No ha sido desarrollado | U16: NOK | V16: 1. No ha sido desarrollado | W16: NOK | X16: 1. No ha sido desarrollado | Y16: NOK | Z16: 1. No ha sido desarrollado | AA16: NOK | AB16: 1. No ha sido desarrollado
B17: 9 | C17: Traceable | E17: NOK | F17: 1. No se tiene una matriz de trazabilidad | G17: NOK | H17: 1. No se tiene una matriz de trazabilidad | I17: NOK | J17: 1. No se tiene una matriz de trazabilidad | K17: NOK | L17: 1. No se tiene una matriz de trazabilidad | M17: NOK | N17: 1. No se tiene una matriz de trazabilidad | O17: NOK | P17: 1. No se tiene una matriz de trazabilidad | Q17: NOK | R17: 1. no se cuenta con una matriz de trazabilidad que cruce formalmente el caso de uso con las reglas de negocio y los futuros casos de prueba | S17: NOK | T17: 1. No se tiene una matriz de trazabilidad | U17: NOK | V17: 1. No se cuenta con una matriz de trazabilidad mapeada hacia los módulos de autenticación y auditoría | W17: NOK | X17: 1. No se tiene una matriz de trazabilidad vinculada a las pantallas de arqueo e inventario. | Y17: NOK | Z17: 1. No se tiene una matriz de trazabilidad | AA17: NOK | AB17: 1. No se tiene matriz de trazabilidad entre este CU automático y el registro del Cajero (CU001.10).
B18: 10 | C18: Complete | E18: OK | F18: 1. Contiene toda la información necesaria (entradas, salidas, precondiciones, postcondiciones) para entender y diseñar la función. 2. Describe completamente la funcionalidad esperada. | G18: OK | H18: 1. Se describe lo que se acordo | I18: OK | J18: 1. Contiene toda la información necesaria para entender y diseñar la función. 2. Describe completamente la funcionalidad esperada. | K18: OK | L18: 1. Contiene toda la información necesaria (entradas, salidas, precondiciones, postcondiciones) para entender y diseñar la función. 2. Describe completamente la funcionalidad esperada. | M18: NOK | N18: 1. Describe entradas y salidas, pero faltan precondiciones y postcondiciones en la ficha del caso de uso. | O18: NOK | P18: 1. Tiene entradas y salidas, pero faltan precondiciones, postcondiciones y flujo 2. No define destinatario ni canal de la notificación; RF-06 solo enlaza al CU | Q18: NOK | R18: 1. Describe correctamente entradas (filtros) y salidas (visualización), pero carece de precondiciones (ej. el usuario debe estar logueado) | S18: NOK | T18: 1. Tiene entradas y salidas, pero faltan precondiciones y postcondiciones 2. No lista los tipos de reporte ni su contenido; RF-08 solo enlaza al CU | U18: NOK | V18: 1. Posee entradas y salidas generales, pero carece de precondiciones (p. ej., sesión activa como Administrador) y postcondiciones. 2. No especifica la estructura del registro de auditoría. | W18: NOK | X18: 1. Tiene entradas (cantidades por producto/turno) y salidas (registro almacenado), pero faltan precondiciones (p. ej., turno abierto) y postcondiciones. 2. Faltan flujos alternativos para conteos incompletos. | Y18: NOK | Z18: 1. Tiene entradas y salidas, pero faltan precondiciones y postcondiciones 2. No lista los tipos de novedad ni formato/límite de la evidencia; RF-11 solo enlaza al CU | AA18: NOK | AB18: 1. Tiene entradas (conteos actuales/anteriores) y salidas (notificación/novedad), pero faltan precondiciones y el canal de notificación (email, alerta en pantalla, etc.).
B19: 11 | C19: Understandability | E19: OK | F19: 1. Se involucra al cliente 2. Existe glosario de términos | G19: OK | H19: 1. Se involucra al cliente | I19: OK | J19: 1. Se involucra al cliente 2. Existe glosario de términos | K19: OK | L19: 1. Se involucra al cliente como fuente de información. 2. Existe glosario (1.4: Stock, Inventario, Trazabilidad); falta el término "Consolidación". | M19: OK | N19: 1. Lenguaje sencillo y digerible para personal no técnico. Se apoya en el glosario de términos. | O19: OK | P19: 1. Se involucra al cliente (1.3) 2. El glosario (1.4) define Stock (existencias); el stock mínimo se explica en Gestionar productos | Q19: OK | R19: 1. Lenguaje sencillo y digerible para personal no técnico. Se apoya en el glosario de términos. | S19: OK | T19: 1. Se involucra al cliente como fuente de información. 2. Existe glosario (1.4: Stock, Inventario, Trazabilidad); falta el término "Consolidación". | U19: NOK | V19: 1. Se involucra al Administrador en el alcance. 2. El glosario no define términos como "rol", "perfil" o "auditoría". | W19: NOK | X19: 1. Se involucra al Cajero en las pruebas de flujo. 2. El glosario no define términos técnicos como "conteo físico" ni "cambio de turno". | Y19: NOK | Z19: 1. Se involucra al cliente (1.3) 2. El glosario (1.4) no define "novedad" ni "conteo físico" | AA19: NOK | AB19: 1. Se contempla la alerta hacia el Administrador. 2. El glosario no define el término "novedad de conteo" ni "inconsistencia consecutiva".

Sheet MODELO LISTA DE COMPROBACIO CU1
B1: SISTEMA: | C1: Sistema de Inventario de Materia Prima (SIMP)
B2: FECHA: | C2: 46297
B3: AUTOR: | C3: Guayanay Lema Erika Vannesa
B4: REQUERIMIENTOS EVALUADOS : | C4: CU001.1 GESTIONAR PRODUCTOS
A6: CONTENIDO
A7: No. | B7: Pregunta | C7: SI | D7: NO
A8: 1 | B8: Todos los requerimientos relevantes se han documentado? | D8: X
A9: 2 | B9: Se han implementado las funciones requeridas? | D9: X
A10: 3 | B10: Existe algún mecanismo que permita seguir el impacto de dicho requerimiento a lo largo del resto de las actividades del ciclo productivo.? | C10: X
A11: 4 | B11: El origen de cada requerimento individual está claro ? | C11: X
A12: 5 | B12: Que tan facil es devolverse a los requerimientos? | C12: X
A13: 6 | B13: Los requerimientos reflejan las necesidades y deseos del cliente? | C13: X
A14: 7 | B14: No hay contradicciones entre los requerimientos? | D14: X
A15: 8 | B15: El requerimiento que se esta especificando contribuye a alcanzar un objetivo definido ? | C15: X
A16: 9 | B16: Existe un proceso acotado (en plazo y presupuesto) que permita determinar que el sistema construido satisface lo descrito en el propio requerimiento? | D16: X
A17: SUMATORIA: | C17: =COUNTA('MODELO LISTA DE COMPROBACIO CU1'!$C$8:$C$16) -> 5 | D17: =COUNTA('MODELO LISTA DE COMPROBACIO CU1'!$D$8:$D$16) -> 4
A18: PORCENTAJE : | C18: =C17/9 -> 0.55555556 | D18: =D17/9 -> 0.44444444
A20: DOCUMENTACIÓN
A21: No. | B21: Pregunta | C21: SI | D21: NO
A22: 1 | B22: Aplica un estandar para la documetación de requerimiento? | C22: X
A23: 2 | B23: Cumple con la estructura definida por el estandar? | C23: X
A24: 3 | B24: Utiliza un Glosario de términos normalizado? | C24: X
A25: 4 | B25: Los requerimientos Funcionales estan sujetos a una única interpretación? | C25: X
A26: 5 | B26: El modelo aplicado cumple con la sintaxis? | C26: X
A27: SUMATORIA: | C27: =COUNTA('MODELO LISTA DE COMPROBACIO CU1'!$C$22:$C$26) -> 5 | D27: =COUNTA('MODELO LISTA DE COMPROBACIO CU1'!$D$22:$D$26) -> 0
A28: PORCENTAJE : | C28: =C27/5 -> 1 | D28: =D27/5 -> 0
A30: NIVEL DE ACUERDO
A31: No. | B31: Pregunta | C31: SI | D31: NO
A32: 1 | B32: Todos los requerimientos han sido acordados con todos los interesados? | C32: X
A33: 2 | B33: Todos los requerimientos modificados han sido acordados por todos los implicados? | C33: X
A34: 3 | B34: Han sido resueltos todos los conflictos conocidos respectos de los requerimientos? | C34: X
A35: SUMATORIA: | C35: =COUNTA('MODELO LISTA DE COMPROBACIO CU1'!$C$32:$C$34) -> 3 | D35: =COUNTA('MODELO LISTA DE COMPROBACIO CU1'!$D$32:$D$34) -> 0
A36: PORCENTAJE : | C36: =C35/3 -> 1 | D36: =D35/3 -> 0
A40: RESUMEN
B41: CONTENIDO | C41: 56
B42: DOCUMENTACIÓN | C42: 100
B43: NIVEL DE ACUERDO | C43: 100

Sheet MODELO LISTA DE COMPROBACIO CU2
B1: SISTEMA: | C1: Sistema de Inventario de Materia Prima (SIMP)
B2: FECHA: | C2: 46297
B3: AUTOR: | C3: Isaac
B4: REQUERIMIENTOS EVALUADOS : | C4: CU001.2 GESTIONAR UNIDADES DE MEDIDA
A6: CONTENIDO
A7: No. | B7: Pregunta | C7: SI | D7: NO
A8: 1 | B8: Todos los requerimientos relevantes se han documentado? | D8: X
A9: 2 | B9: Se han implementado las funciones requeridas? | D9: X
A10: 3 | B10: Existe algún mecanismo que permita seguir el impacto de dicho requerimiento a lo largo del resto de las actividades del ciclo productivo.? | C10: X
A11: 4 | B11: El origen de cada requerimento individual está claro ? | C11: X
A12: 5 | B12: Que tan facil es devolverse a los requerimientos? | C12: X
A13: 6 | B13: Los requerimientos reflejan las necesidades y deseos del cliente? | C13: X
A14: 7 | B14: No hay contradicciones entre los requerimientos? | D14: X
A15: 8 | B15: El requerimiento que se esta especificando contribuye a alcanzar un objetivo definido ? | C15: X
A16: 9 | B16: Existe un proceso acotado (en plazo y presupuesto) que permita determinar que el sistema construido satisface lo descrito en el propio requerimiento? | D16: X
A17: SUMATORIA: | C17: =COUNTA('MODELO LISTA DE COMPROBACIO CU2'!$C$8:$C$16) -> 5 | D17: =COUNTA('MODELO LISTA DE COMPROBACIO CU2'!$D$8:$D$16) -> 4
A18: PORCENTAJE : | C18: =C17/9 -> 0.55555556 | D18: =D17/9 -> 0.44444444
A20: DOCUMENTACIÓN
A21: No. | B21: Pregunta | C21: SI | D21: NO
A22: 1 | B22: Aplica un estandar para la documetación de requerimiento? | C22: X
A23: 2 | B23: Cumple con la estructura definida por el estandar? | C23: X
A24: 3 | B24: Utiliza un Glosario de términos normalizado? | D24: X
A25: 4 | B25: Los requerimientos Funcionales estan sujetos a una única interpretación? | C25: X
A26: 5 | B26: El modelo aplicado cumple con la sintaxis? | C26: X
A27: SUMATORIA: | C27: =COUNTA('MODELO LISTA DE COMPROBACIO CU2'!$C$22:$C$26) -> 4 | D27: =COUNTA('MODELO LISTA DE COMPROBACIO CU2'!$D$22:$D$26) -> 1
A28: PORCENTAJE : | C28: =C27/5 -> 0.8 | D28: =D27/5 -> 0.2
A30: NIVEL DE ACUERDO
A31: No. | B31: Pregunta | C31: SI | D31: NO
A32: 1 | B32: Todos los requerimientos han sido acordados con todos los interesados? | C32: X
A33: 2 | B33: Todos los requerimientos modificados han sido acordados por todos los implicados? | C33: X
A34: 3 | B34: Han sido resueltos todos los conflictos conocidos respectos de los requerimientos? | C34: X
A35: SUMATORIA: | C35: =COUNTA('MODELO LISTA DE COMPROBACIO CU2'!$C$32:$C$34) -> 3 | D35: =COUNTA('MODELO LISTA DE COMPROBACIO CU2'!$D$32:$D$34) -> 0
A36: PORCENTAJE : | C36: =C35/3 -> 1 | D36: =D35/3 -> 0
A40: RESUMEN
B41: CONTENIDO | C41: 56
B42: DOCUMENTACIÓN | C42: 100
B43: NIVEL DE ACUERDO | C43: 100

Sheet MODELO LISTA DE COMPROBACIO CU4
B1: SISTEMA: | C1: Sistema de Inventario de Materia Prima (SIMP)
B2: FECHA: | C2: 46297
B3: AUTOR: | C3: Báez Jaramillo, Gabriel Alejandro
B4: REQUERIMIENTOS EVALUADOS : | C4: CU4 Consolidar Inventario del sistema
A6: CONTENIDO
A7: No. | B7: Pregunta | C7: SI | D7: NO
A8: 1 | B8: Todos los requerimientos relevantes se han documentado? | D8: X
A9: 2 | B9: Se han implementado las funciones requeridas? | D9: X
A10: 3 | B10: Existe algún mecanismo que permita seguir el impacto de dicho requerimiento a lo largo del resto de las actividades del ciclo productivo.? | C10: X
A11: 4 | B11: El origen de cada requerimento individual está claro ? | C11: X
A12: 5 | B12: Que tan facil es devolverse a los requerimientos? | C12: X
A13: 6 | B13: Los requerimientos reflejan las necesidades y deseos del cliente? | C13: X
A14: 7 | B14: No hay contradicciones entre los requerimientos? | D14: X
A15: 8 | B15: El requerimiento que se esta especificando contribuye a alcanzar un objetivo definido ? | C15: X
A16: 9 | B16: Existe un proceso acotado (en plazo y presupuesto) que permita determinar que el sistema construido satisface lo descrito en el propio requerimiento? | D16: X
A17: SUMATORIA: | C17: =COUNTA('MODELO LISTA DE COMPROBACIO CU4'!$C$8:$C$16) -> 5 | D17: =COUNTA('MODELO LISTA DE COMPROBACIO CU4'!$D$8:$D$16) -> 4
A18: PORCENTAJE : | C18: =C17/9 -> 0.55555556 | D18: =D17/9 -> 0.44444444
A20: DOCUMENTACIÓN
A21: No. | B21: Pregunta | C21: SI | D21: NO
A22: 1 | B22: Aplica un estandar para la documetación de requerimiento? | C22: X
A23: 2 | B23: Cumple con la estructura definida por el estandar? | C23: X
A24: 3 | B24: Utiliza un Glosario de términos normalizado? | C24: X
A25: 4 | B25: Los requerimientos Funcionales estan sujetos a una única interpretación? | D25: X
A26: 5 | B26: El modelo aplicado cumple con la sintaxis? | C26: X
A27: SUMATORIA: | C27: =COUNTA('MODELO LISTA DE COMPROBACIO CU4'!$C$22:$C$26) -> 4 | D27: =COUNTA('MODELO LISTA DE COMPROBACIO CU4'!$D$22:$D$26) -> 1
A28: PORCENTAJE : | C28: =C27/5 -> 0.8 | D28: =D27/5 -> 0.2
A30: NIVEL DE ACUERDO
A31: No. | B31: Pregunta | C31: SI | D31: NO
A32: 1 | B32: Todos los requerimientos han sido acordados con todos los interesados? | C32: X
A33: 2 | B33: Todos los requerimientos modificados han sido acordados por todos los implicados? | C33: X
A34: 3 | B34: Han sido resueltos todos los conflictos conocidos respectos de los requerimientos? | C34: X
A35: SUMATORIA: | C35: =COUNTA('MODELO LISTA DE COMPROBACIO CU4'!$C$32:$C$34) -> 3 | D35: =COUNTA('MODELO LISTA DE COMPROBACIO CU4'!$D$32:$D$34) -> 0
A36: PORCENTAJE : | C36: =C35/3 -> 1 | D36: =D35/3 -> 0
A40: RESUMEN
B41: CONTENIDO | C41: 56
B42: DOCUMENTACIÓN | C42: 80
B43: NIVEL DE ACUERDO | C43: 100

Sheet MODELO LISTA DE COMPROBACI CU6
B1: SISTEMA: | C1: Sistema de Inventario de Materia Prima (SIMP)
B2: FECHA: | C2: 46297
B3: AUTOR: | C3: Báez Jaramillo, Gabriel Alejandro
B4: REQUERIMIENTOS EVALUADOS : | C4: CU6 Alertar de Cantidad de Existencias Baja
A6: CONTENIDO
A7: No. | B7: Pregunta | C7: SI | D7: NO
A8: 1 | B8: Todos los requerimientos relevantes se han documentado? | D8: X
A9: 2 | B9: Se han implementado las funciones requeridas? | D9: X
A10: 3 | B10: Existe algún mecanismo que permita seguir el impacto de dicho requerimiento a lo largo del resto de las actividades del ciclo productivo.? | D10: X
A11: 4 | B11: El origen de cada requerimento individual está claro ? | C11: X
A12: 5 | B12: Que tan facil es devolverse a los requerimientos? | C12: X
A13: 6 | B13: Los requerimientos reflejan las necesidades y deseos del cliente? | C13: X
A14: 7 | B14: No hay contradicciones entre los requerimientos? | D14: X
A15: 8 | B15: El requerimiento que se esta especificando contribuye a alcanzar un objetivo definido ? | C15: X
A16: 9 | B16: Existe un proceso acotado (en plazo y presupuesto) que permita determinar que el sistema construido satisface lo descrito en el propio requerimiento? | D16: X
A17: SUMATORIA: | C17: =COUNTA('MODELO LISTA DE COMPROBACI CU6'!$C$8:$C$16) -> 4 | D17: =COUNTA('MODELO LISTA DE COMPROBACI CU6'!$D$8:$D$16) -> 5
A18: PORCENTAJE : | C18: =C17/9 -> 0.44444444 | D18: =D17/9 -> 0.55555556
A20: DOCUMENTACIÓN
A21: No. | B21: Pregunta | C21: SI | D21: NO
A22: 1 | B22: Aplica un estandar para la documetación de requerimiento? | C22: X
A23: 2 | B23: Cumple con la estructura definida por el estandar? | C23: X
A24: 3 | B24: Utiliza un Glosario de términos normalizado? | C24: X
A25: 4 | B25: Los requerimientos Funcionales estan sujetos a una única interpretación? | D25: X
A26: 5 | B26: El modelo aplicado cumple con la sintaxis? | C26: X
A27: SUMATORIA: | C27: =COUNTA('MODELO LISTA DE COMPROBACI CU6'!$C$22:$C$26) -> 4 | D27: =COUNTA('MODELO LISTA DE COMPROBACI CU6'!$D$22:$D$26) -> 1
A28: PORCENTAJE : | C28: =C27/5 -> 0.8 | D28: =D27/5 -> 0.2
A30: NIVEL DE ACUERDO
A31: No. | B31: Pregunta | C31: SI | D31: NO
A32: 1 | B32: Todos los requerimientos han sido acordados con todos los interesados? | C32: X
A33: 2 | B33: Todos los requerimientos modificados han sido acordados por todos los implicados? | C33: X
A34: 3 | B34: Han sido resueltos todos los conflictos conocidos respectos de los requerimientos? | C34: X
A35: SUMATORIA: | C35: =COUNTA('MODELO LISTA DE COMPROBACI CU6'!$C$32:$C$34) -> 3 | D35: =COUNTA('MODELO LISTA DE COMPROBACI CU6'!$D$32:$D$34) -> 0
A36: PORCENTAJE : | C36: =C35/3 -> 1 | D36: =D35/3 -> 0
A40: RESUMEN
B41: CONTENIDO | C41: 44
B42: DOCUMENTACIÓN | C42: 80
B43: NIVEL DE ACUERDO | C43: 100

Sheet MODELO LISTA DE COMPROBACIO CU8
B1: SISTEMA: | C1: Sistema de Inventario de Materia Prima (SIMP)
B2: FECHA: | C2: 46297
B3: AUTOR: | C3: Báez Jaramillo, Gabriel Alejandro
B4: REQUERIMIENTOS EVALUADOS : | C4: CU8 Generar Reportes de Inventario
A6: CONTENIDO
A7: No. | B7: Pregunta | C7: SI | D7: NO
A8: 1 | B8: Todos los requerimientos relevantes se han documentado? | D8: X
A9: 2 | B9: Se han implementado las funciones requeridas? | D9: X
A10: 3 | B10: Existe algún mecanismo que permita seguir el impacto de dicho requerimiento a lo largo del resto de las actividades del ciclo productivo.? | D10: X
A11: 4 | B11: El origen de cada requerimento individual está claro ? | C11: X
A12: 5 | B12: Que tan facil es devolverse a los requerimientos? | C12: X
A13: 6 | B13: Los requerimientos reflejan las necesidades y deseos del cliente? | C13: X
A14: 7 | B14: No hay contradicciones entre los requerimientos? | C14: X
A15: 8 | B15: El requerimiento que se esta especificando contribuye a alcanzar un objetivo definido ? | C15: X
A16: 9 | B16: Existe un proceso acotado (en plazo y presupuesto) que permita determinar que el sistema construido satisface lo descrito en el propio requerimiento? | D16: X
A17: SUMATORIA: | C17: =COUNTA('MODELO LISTA DE COMPROBACIO CU8'!$C$8:$C$16) -> 5 | D17: =COUNTA('MODELO LISTA DE COMPROBACIO CU8'!$D$8:$D$16) -> 4
A18: PORCENTAJE : | C18: =C17/9 -> 0.55555556 | D18: =D17/9 -> 0.44444444
A20: DOCUMENTACIÓN
A21: No. | B21: Pregunta | C21: SI | D21: NO
A22: 1 | B22: Aplica un estandar para la documetación de requerimiento? | C22: X
A23: 2 | B23: Cumple con la estructura definida por el estandar? | C23: X
A24: 3 | B24: Utiliza un Glosario de términos normalizado? | C24: X
A25: 4 | B25: Los requerimientos Funcionales estan sujetos a una única interpretación? | D25: X
A26: 5 | B26: El modelo aplicado cumple con la sintaxis? | C26: X
A27: SUMATORIA: | C27: =COUNTA('MODELO LISTA DE COMPROBACIO CU8'!$C$22:$C$26) -> 4 | D27: =COUNTA('MODELO LISTA DE COMPROBACIO CU8'!$D$22:$D$26) -> 1
A28: PORCENTAJE : | C28: =C27/5 -> 0.8 | D28: =D27/5 -> 0.2
A30: NIVEL DE ACUERDO
A31: No. | B31: Pregunta | C31: SI | D31: NO
A32: 1 | B32: Todos los requerimientos han sido acordados con todos los interesados? | C32: X
A33: 2 | B33: Todos los requerimientos modificados han sido acordados por todos los implicados? | C33: X
A34: 3 | B34: Han sido resueltos todos los conflictos conocidos respectos de los requerimientos? | C34: X
A35: SUMATORIA: | C35: =COUNTA('MODELO LISTA DE COMPROBACIO CU8'!$C$32:$C$34) -> 3 | D35: =COUNTA('MODELO LISTA DE COMPROBACIO CU8'!$D$32:$D$34) -> 0
A36: PORCENTAJE : | C36: =C35/3 -> 1 | D36: =D35/3 -> 0
A40: RESUMEN
B41: CONTENIDO | C41: 56
B42: DOCUMENTACIÓN | C42: 80
B43: NIVEL DE ACUERDO | C43: 100

Sheet MODELO LISTA DE COMPROBACIOCU11
B1: SISTEMA: | C1: Sistema de Inventario de Materia Prima (SIMP)
B2: FECHA: | C2: 46297
B3: AUTOR: | C3: Báez Jaramillo, Gabriel Alejandro
B4: REQUERIMIENTOS EVALUADOS : | C4: CU11 Registrar Novedades de Inventario
A6: CONTENIDO
A7: No. | B7: Pregunta | C7: SI | D7: NO
A8: 1 | B8: Todos los requerimientos relevantes se han documentado? | D8: X
A9: 2 | B9: Se han implementado las funciones requeridas? | D9: X
A10: 3 | B10: Existe algún mecanismo que permita seguir el impacto de dicho requerimiento a lo largo del resto de las actividades del ciclo productivo.? | D10: X
A11: 4 | B11: El origen de cada requerimento individual está claro ? | C11: X
A12: 5 | B12: Que tan facil es devolverse a los requerimientos? | D12: X
A13: 6 | B13: Los requerimientos reflejan las necesidades y deseos del cliente? | C13: X
A14: 7 | B14: No hay contradicciones entre los requerimientos? | D14: X
A15: 8 | B15: El requerimiento que se esta especificando contribuye a alcanzar un objetivo definido ? | C15: X
A16: 9 | B16: Existe un proceso acotado (en plazo y presupuesto) que permita determinar que el sistema construido satisface lo descrito en el propio requerimiento? | D16: X
A17: SUMATORIA: | C17: =COUNTA('MODELO LISTA DE COMPROBACIOCU11'!$C$8:$C$16) -> 3 | D17: =COUNTA('MODELO LISTA DE COMPROBACIOCU11'!$D$8:$D$16) -> 6
A18: PORCENTAJE : | C18: =C17/9 -> 0.33333333 | D18: =D17/9 -> 0.66666667
A20: DOCUMENTACIÓN
A21: No. | B21: Pregunta | C21: SI | D21: NO
A22: 1 | B22: Aplica un estandar para la documetación de requerimiento? | C22: X
A23: 2 | B23: Cumple con la estructura definida por el estandar? | D23: X
A24: 3 | B24: Utiliza un Glosario de términos normalizado? | D24: X
A25: 4 | B25: Los requerimientos Funcionales estan sujetos a una única interpretación? | C25: X
A26: 5 | B26: El modelo aplicado cumple con la sintaxis? | C26: X
A27: SUMATORIA: | C27: =COUNTA('MODELO LISTA DE COMPROBACIOCU11'!$C$22:$C$26) -> 3 | D27: =COUNTA('MODELO LISTA DE COMPROBACIOCU11'!$D$22:$D$26) -> 2
A28: PORCENTAJE : | C28: =C27/5 -> 0.6 | D28: =D27/5 -> 0.4
A30: NIVEL DE ACUERDO
A31: No. | B31: Pregunta | C31: SI | D31: NO
A32: 1 | B32: Todos los requerimientos han sido acordados con todos los interesados? | C32: X
A33: 2 | B33: Todos los requerimientos modificados han sido acordados por todos los implicados? | C33: X
A34: 3 | B34: Han sido resueltos todos los conflictos conocidos respectos de los requerimientos? | C34: X
A35: SUMATORIA: | C35: =COUNTA('MODELO LISTA DE COMPROBACIOCU11'!$C$32:$C$34) -> 3 | D35: =COUNTA('MODELO LISTA DE COMPROBACIOCU11'!$D$32:$D$34) -> 0
A36: PORCENTAJE : | C36: =C35/3 -> 1 | D36: =D35/3 -> 0
A40: RESUMEN
B41: CONTENIDO | C41: 33
B42: DOCUMENTACIÓN | C42: 60
B43: NIVEL DE ACUERDO | C43: 100

Sheet MODELO LISTA DE COMPROBACIO CU7
B1: SISTEMA: | C1: Sistema de Inventario de Materia Prima (SIMP)
B2: FECHA: | C2: 46297
B3: AUTOR: | C3: Guayanay Lema Erika Vannesa
B4: REQUERIMIENTOS EVALUADOS : | C4: CU001.7 Consultar Existencias
A6: CONTENIDO
A7: No. | B7: Pregunta | C7: SI | D7: NO
A8: 1 | B8: Todos los requerimientos relevantes se han documentado? | C8: X
A9: 2 | B9: Se han implementado las funciones requeridas? | D9: X
A10: 3 | B10: Existe algún mecanismo que permita seguir el impacto de dicho requerimiento a lo largo del resto de las actividades del ciclo productivo.? | D10: X
A11: 4 | B11: El origen de cada requerimento individual está claro ? | C11: X
A12: 5 | B12: Que tan facil es devolverse a los requerimientos? | C12: X
A13: 6 | B13: Los requerimientos reflejan las necesidades y deseos del cliente? | C13: X
A14: 7 | B14: No hay contradicciones entre los requerimientos? | C14: X
A15: 8 | B15: El requerimiento que se esta especificando contribuye a alcanzar un objetivo definido ? | C15: X
A16: 9 | B16: Existe un proceso acotado (en plazo y presupuesto) que permita determinar que el sistema construido satisface lo descrito en el propio requerimiento? | D16: X
A17: SUMATORIA: | C17: =COUNTA('MODELO LISTA DE COMPROBACIO CU7'!$C$8:$C$16) -> 6 | D17: =COUNTA('MODELO LISTA DE COMPROBACIO CU7'!$D$8:$D$16) -> 3
A18: PORCENTAJE : | C18: =C17/9 -> 0.66666667 | D18: =D17/9 -> 0.33333333
A20: DOCUMENTACIÓN
A21: No. | B21: Pregunta | C21: SI | D21: NO
A22: 1 | B22: Aplica un estandar para la documetación de requerimiento? | C22: X
A23: 2 | B23: Cumple con la estructura definida por el estandar? | C23: X
A24: 3 | B24: Utiliza un Glosario de términos normalizado? | C24: X
A25: 4 | B25: Los requerimientos Funcionales estan sujetos a una única interpretación? | C25: X
A26: 5 | B26: El modelo aplicado cumple con la sintaxis? | C26: X
A27: SUMATORIA: | C27: =COUNTA('MODELO LISTA DE COMPROBACIO CU7'!$C$22:$C$26) -> 5 | D27: =COUNTA('MODELO LISTA DE COMPROBACIO CU7'!$D$22:$D$26) -> 0
A28: PORCENTAJE : | C28: =C27/5 -> 1 | D28: =D27/5 -> 0
A30: NIVEL DE ACUERDO
A31: No. | B31: Pregunta | C31: SI | D31: NO
A32: 1 | B32: Todos los requerimientos han sido acordados con todos los interesados? | C32: X
A33: 2 | B33: Todos los requerimientos modificados han sido acordados por todos los implicados? | C33: X
A34: 3 | B34: Han sido resueltos todos los conflictos conocidos respectos de los requerimientos? | C34: X
A35: SUMATORIA: | C35: =COUNTA('MODELO LISTA DE COMPROBACIO CU7'!$C$32:$C$34) -> 3 | D35: =COUNTA('MODELO LISTA DE COMPROBACIO CU7'!$D$32:$D$34) -> 0
A36: PORCENTAJE : | C36: =C35/3 -> 1 | D36: =D35/3 -> 0
A40: RESUMEN
B41: CONTENIDO | C41: 67
B42: DOCUMENTACIÓN | C42: 100
B43: NIVEL DE ACUERDO | C43: 100

Sheet MODELO LISTA DE COMPROBACIO CU5
B1: SISTEMA: | C1: Sistema de Inventario de Materia Prima (SIMP)
B2: FECHA: | C2: 46297
B3: AUTOR: | C3: Guayanay Lema Erika Vannesa
B4: REQUERIMIENTOS EVALUADOS : | C4: CU001.5 Gestionar compras
A6: CONTENIDO
A7: No. | B7: Pregunta | C7: SI | D7: NO
A8: 1 | B8: Todos los requerimientos relevantes se han documentado? | C8: X
A9: 2 | B9: Se han implementado las funciones requeridas? | D9: X
A10: 3 | B10: Existe algún mecanismo que permita seguir el impacto de dicho requerimiento a lo largo del resto de las actividades del ciclo productivo.? | D10: X
A11: 4 | B11: El origen de cada requerimento individual está claro ? | C11: X
A12: 5 | B12: Que tan facil es devolverse a los requerimientos? | C12: X
A13: 6 | B13: Los requerimientos reflejan las necesidades y deseos del cliente? | C13: X
A14: 7 | B14: No hay contradicciones entre los requerimientos? | C14: X
A15: 8 | B15: El requerimiento que se esta especificando contribuye a alcanzar un objetivo definido ? | C15: X
A16: 9 | B16: Existe un proceso acotado (en plazo y presupuesto) que permita determinar que el sistema construido satisface lo descrito en el propio requerimiento? | D16: X
A17: SUMATORIA: | C17: =COUNTA('MODELO LISTA DE COMPROBACIO CU5'!$C$8:$C$16) -> 6 | D17: =COUNTA('MODELO LISTA DE COMPROBACIO CU5'!$D$8:$D$16) -> 3
A18: PORCENTAJE : | C18: =C17/9 -> 0.66666667 | D18: =D17/9 -> 0.33333333
A20: DOCUMENTACIÓN
A21: No. | B21: Pregunta | C21: SI | D21: NO
A22: 1 | B22: Aplica un estandar para la documetación de requerimiento? | C22: X
A23: 2 | B23: Cumple con la estructura definida por el estandar? | C23: X
A24: 3 | B24: Utiliza un Glosario de términos normalizado? | C24: X
A25: 4 | B25: Los requerimientos Funcionales estan sujetos a una única interpretación? | C25: X
A26: 5 | B26: El modelo aplicado cumple con la sintaxis? | C26: X
A27: SUMATORIA: | C27: =COUNTA('MODELO LISTA DE COMPROBACIO CU5'!$C$22:$C$26) -> 5 | D27: =COUNTA('MODELO LISTA DE COMPROBACIO CU5'!$D$22:$D$26) -> 0
A28: PORCENTAJE : | C28: =C27/5 -> 1 | D28: =D27/5 -> 0
A30: NIVEL DE ACUERDO
A31: No. | B31: Pregunta | C31: SI | D31: NO
A32: 1 | B32: Todos los requerimientos han sido acordados con todos los interesados? | C32: X
A33: 2 | B33: Todos los requerimientos modificados han sido acordados por todos los implicados? | C33: X
A34: 3 | B34: Han sido resueltos todos los conflictos conocidos respectos de los requerimientos? | C34: X
A35: SUMATORIA: | C35: =COUNTA('MODELO LISTA DE COMPROBACIO CU5'!$C$32:$C$34) -> 3 | D35: =COUNTA('MODELO LISTA DE COMPROBACIO CU5'!$D$32:$D$34) -> 0
A36: PORCENTAJE : | C36: =C35/3 -> 1 | D36: =D35/3 -> 0
A40: RESUMEN
B41: CONTENIDO | C41: 67
B42: DOCUMENTACIÓN | C42: 100
B43: NIVEL DE ACUERDO | C43: 100

Sheet MODELO LISTA DE COMPROBACIO CU3
B1: SISTEMA: | C1: Sistema de Inventario de Materia Prima (SIMP)
B2: FECHA: | C2: 46297
B3: AUTOR: | C3: Guayanay Lema Erika Vannesa
B4: REQUERIMIENTOS EVALUADOS : | C4: CU001.3 Gestionar categorías de inventario
A6: CONTENIDO
A7: No. | B7: Pregunta | C7: SI | D7: NO
A8: 1 | B8: Todos los requerimientos relevantes se han documentado? | C8: X
A9: 2 | B9: Se han implementado las funciones requeridas? | D9: X
A10: 3 | B10: Existe algún mecanismo que permita seguir el impacto de dicho requerimiento a lo largo del resto de las actividades del ciclo productivo.? | D10: X
A11: 4 | B11: El origen de cada requerimento individual está claro ? | C11: X
A12: 5 | B12: Que tan facil es devolverse a los requerimientos? | C12: X
A13: 6 | B13: Los requerimientos reflejan las necesidades y deseos del cliente? | C13: X
A14: 7 | B14: No hay contradicciones entre los requerimientos? | C14: X
A15: 8 | B15: El requerimiento que se esta especificando contribuye a alcanzar un objetivo definido ? | C15: X
A16: 9 | B16: Existe un proceso acotado (en plazo y presupuesto) que permita determinar que el sistema construido satisface lo descrito en el propio requerimiento? | D16: X
A17: SUMATORIA: | C17: =COUNTA('MODELO LISTA DE COMPROBACIO CU3'!$C$8:$C$16) -> 6 | D17: =COUNTA('MODELO LISTA DE COMPROBACIO CU3'!$D$8:$D$16) -> 3
A18: PORCENTAJE : | C18: =C17/9 -> 0.66666667 | D18: =D17/9 -> 0.33333333
A20: DOCUMENTACIÓN
A21: No. | B21: Pregunta | C21: SI | D21: NO
A22: 1 | B22: Aplica un estandar para la documetación de requerimiento? | C22: X
A23: 2 | B23: Cumple con la estructura definida por el estandar? | C23: X
A24: 3 | B24: Utiliza un Glosario de términos normalizado? | C24: X
A25: 4 | B25: Los requerimientos Funcionales estan sujetos a una única interpretación? | C25: X
A26: 5 | B26: El modelo aplicado cumple con la sintaxis? | C26: X
A27: SUMATORIA: | C27: =COUNTA('MODELO LISTA DE COMPROBACIO CU3'!$C$22:$C$26) -> 5 | D27: =COUNTA('MODELO LISTA DE COMPROBACIO CU3'!$D$22:$D$26) -> 0
A28: PORCENTAJE : | C28: =C27/5 -> 1 | D28: =D27/5 -> 0
A30: NIVEL DE ACUERDO
A31: No. | B31: Pregunta | C31: SI | D31: NO
A32: 1 | B32: Todos los requerimientos han sido acordados con todos los interesados? | C32: X
A33: 2 | B33: Todos los requerimientos modificados han sido acordados por todos los implicados? | C33: X
A34: 3 | B34: Han sido resueltos todos los conflictos conocidos respectos de los requerimientos? | C34: X
A35: SUMATORIA: | C35: =COUNTA('MODELO LISTA DE COMPROBACIO CU3'!$C$32:$C$34) -> 3 | D35: =COUNTA('MODELO LISTA DE COMPROBACIO CU3'!$D$32:$D$34) -> 0
A36: PORCENTAJE : | C36: =C35/3 -> 1 | D36: =D35/3 -> 0
A40: RESUMEN
B41: CONTENIDO | C41: 67
B42: DOCUMENTACIÓN | C42: 100
B43: NIVEL DE ACUERDO | C43: 100

Sheet MODELO LISTA DE COMPROBACIO CU9
B1: SISTEMA: | C1: Sistema de Inventario de Materia Prima (SIMP)
B2: FECHA: | C2: 46297
B3: AUTOR: | C3: Isaac
B4: REQUERIMIENTOS EVALUADOS : | C4: CU001.9 — Administrar sistema
A6: CONTENIDO
A7: No. | B7: Pregunta | C7: SI | D7: NO
A8: 1 | B8: Todos los requerimientos relevantes se han documentado? | D8: X
A9: 2 | B9: Se han implementado las funciones requeridas? | D9: X
A10: 3 | B10: Existe algún mecanismo que permita seguir el impacto de dicho requerimiento a lo largo del resto de las actividades del ciclo productivo.? | D10: X
A11: 4 | B11: El origen de cada requerimento individual está claro ? | C11: X
A12: 5 | B12: Que tan facil es devolverse a los requerimientos? | C12: X
A13: 6 | B13: Los requerimientos reflejan las necesidades y deseos del cliente? | C13: X
A14: 7 | B14: No hay contradicciones entre los requerimientos? | D14: X
A15: 8 | B15: El requerimiento que se esta especificando contribuye a alcanzar un objetivo definido ? | C15: X
A16: 9 | B16: Existe un proceso acotado (en plazo y presupuesto) que permita determinar que el sistema construido satisface lo descrito en el propio requerimiento? | D16: X
A17: SUMATORIA: | C17: =COUNTA('MODELO LISTA DE COMPROBACIO CU9'!$C$8:$C$16) -> 4 | D17: =COUNTA('MODELO LISTA DE COMPROBACIO CU9'!$D$8:$D$16) -> 5
A18: PORCENTAJE : | C18: =C17/9 -> 0.44444444 | D18: =D17/9 -> 0.55555556
A20: DOCUMENTACIÓN
A21: No. | B21: Pregunta | C21: SI | D21: NO
A22: 1 | B22: Aplica un estandar para la documetación de requerimiento? | C22: X
A23: 2 | B23: Cumple con la estructura definida por el estandar? | C23: X
A24: 3 | B24: Utiliza un Glosario de términos normalizado? | D24: X
A25: 4 | B25: Los requerimientos Funcionales estan sujetos a una única interpretación? | C25: X
A26: 5 | B26: El modelo aplicado cumple con la sintaxis? | C26: X
A27: SUMATORIA: | C27: =COUNTA('MODELO LISTA DE COMPROBACIO CU9'!$C$22:$C$26) -> 4 | D27: =COUNTA('MODELO LISTA DE COMPROBACIO CU9'!$D$22:$D$26) -> 1
A28: PORCENTAJE : | C28: =C27/5 -> 0.8 | D28: =D27/5 -> 0.2
A30: NIVEL DE ACUERDO
A31: No. | B31: Pregunta | C31: SI | D31: NO
A32: 1 | B32: Todos los requerimientos han sido acordados con todos los interesados? | C32: X
A33: 2 | B33: Todos los requerimientos modificados han sido acordados por todos los implicados? | C33: X
A34: 3 | B34: Han sido resueltos todos los conflictos conocidos respectos de los requerimientos? | C34: X
A35: SUMATORIA: | C35: =COUNTA('MODELO LISTA DE COMPROBACIO CU9'!$C$32:$C$34) -> 3 | D35: =COUNTA('MODELO LISTA DE COMPROBACIO CU9'!$D$32:$D$34) -> 0
A36: PORCENTAJE : | C36: =C35/3 -> 1 | D36: =D35/3 -> 0
A40: RESUMEN
B41: CONTENIDO | C41: 56
B42: DOCUMENTACIÓN | C42: 100
B43: NIVEL DE ACUERDO | C43: 100

Sheet MODELO LISTA DE COMPROBACIOCU12
B1: SISTEMA: | C1: Sistema de Inventario de Materia Prima (SIMP)
B2: FECHA: | C2: 46297
B3: AUTOR: | C3: Isaac
B4: REQUERIMIENTOS EVALUADOS : | C4: CU001.12 — Registrar automáticamente novedades de conteo
A6: CONTENIDO
A7: No. | B7: Pregunta | C7: SI | D7: NO
A8: 1 | B8: Todos los requerimientos relevantes se han documentado? | D8: X
A9: 2 | B9: Se han implementado las funciones requeridas? | D9: X
A10: 3 | B10: Existe algún mecanismo que permita seguir el impacto de dicho requerimiento a lo largo del resto de las actividades del ciclo productivo.? | D10: X
A11: 4 | B11: El origen de cada requerimento individual está claro ? | D11: X
A12: 5 | B12: Que tan facil es devolverse a los requerimientos? | C12: X
A13: 6 | B13: Los requerimientos reflejan las necesidades y deseos del cliente? | C13: X
A14: 7 | B14: No hay contradicciones entre los requerimientos? | D14: X
A15: 8 | B15: El requerimiento que se esta especificando contribuye a alcanzar un objetivo definido ? | C15: X
A16: 9 | B16: Existe un proceso acotado (en plazo y presupuesto) que permita determinar que el sistema construido satisface lo descrito en el propio requerimiento? | D16: X
A17: SUMATORIA: | C17: =COUNTA('MODELO LISTA DE COMPROBACIOCU12'!$C$8:$C$16) -> 3 | D17: =COUNTA('MODELO LISTA DE COMPROBACIOCU12'!$D$8:$D$16) -> 6
A18: PORCENTAJE : | C18: =C17/9 -> 0.33333333 | D18: =D17/9 -> 0.66666667
A20: DOCUMENTACIÓN
A21: No. | B21: Pregunta | C21: SI | D21: NO
A22: 1 | B22: Aplica un estandar para la documetación de requerimiento? | C22: X
A23: 2 | B23: Cumple con la estructura definida por el estandar? | C23: X
A24: 3 | B24: Utiliza un Glosario de términos normalizado? | D24: X
A25: 4 | B25: Los requerimientos Funcionales estan sujetos a una única interpretación? | D25: X
A26: 5 | B26: El modelo aplicado cumple con la sintaxis? | C26: X
A27: SUMATORIA: | C27: =COUNTA('MODELO LISTA DE COMPROBACIOCU12'!$C$22:$C$26) -> 3 | D27: =COUNTA('MODELO LISTA DE COMPROBACIOCU12'!$D$22:$D$26) -> 2
A28: PORCENTAJE : | C28: =C27/5 -> 0.6 | D28: =D27/5 -> 0.4
A30: NIVEL DE ACUERDO
A31: No. | B31: Pregunta | C31: SI | D31: NO
A32: 1 | B32: Todos los requerimientos han sido acordados con todos los interesados? | C32: X
A33: 2 | B33: Todos los requerimientos modificados han sido acordados por todos los implicados? | C33: X
A34: 3 | B34: Han sido resueltos todos los conflictos conocidos respectos de los requerimientos? | C34: X
A35: SUMATORIA: | C35: =COUNTA('MODELO LISTA DE COMPROBACIOCU12'!$C$32:$C$34) -> 3 | D35: =COUNTA('MODELO LISTA DE COMPROBACIOCU12'!$D$32:$D$34) -> 0
A36: PORCENTAJE : | C36: =C35/3 -> 1 | D36: =D35/3 -> 0
A40: RESUMEN
B41: CONTENIDO | C41: 56
B42: DOCUMENTACIÓN | C42: 100
B43: NIVEL DE ACUERDO | C43: 100

Sheet MODELO LISTA DE COMPROBACIOCU10
B1: SISTEMA: | C1: Sistema de Inventario de Materia Prima (SIMP)
B2: FECHA: | C2: 46297
B3: AUTOR: | C3: Isaac
B4: REQUERIMIENTOS EVALUADOS : | C4: CU001.10 — Registrar estado físico del inventario
A6: CONTENIDO
A7: No. | B7: Pregunta | C7: SI | D7: NO
A8: 1 | B8: Todos los requerimientos relevantes se han documentado? | D8: X
A9: 2 | B9: Se han implementado las funciones requeridas? | D9: X
A10: 3 | B10: Existe algún mecanismo que permita seguir el impacto de dicho requerimiento a lo largo del resto de las actividades del ciclo productivo.? | D10: X
A11: 4 | B11: El origen de cada requerimento individual está claro ? | C11: X
A12: 5 | B12: Que tan facil es devolverse a los requerimientos? | C12: X
A13: 6 | B13: Los requerimientos reflejan las necesidades y deseos del cliente? | C13: X
A14: 7 | B14: No hay contradicciones entre los requerimientos? | D14: X
A15: 8 | B15: El requerimiento que se esta especificando contribuye a alcanzar un objetivo definido ? | C15: X
A16: 9 | B16: Existe un proceso acotado (en plazo y presupuesto) que permita determinar que el sistema construido satisface lo descrito en el propio requerimiento? | D16: X
A17: SUMATORIA: | C17: =COUNTA('MODELO LISTA DE COMPROBACIOCU10'!$C$8:$C$16) -> 4 | D17: =COUNTA('MODELO LISTA DE COMPROBACIOCU10'!$D$8:$D$16) -> 5
A18: PORCENTAJE : | C18: =C17/9 -> 0.44444444 | D18: =D17/9 -> 0.55555556
A20: DOCUMENTACIÓN
A21: No. | B21: Pregunta | C21: SI | D21: NO
A22: 1 | B22: Aplica un estandar para la documetación de requerimiento? | C22: X
A23: 2 | B23: Cumple con la estructura definida por el estandar? | C23: X
A24: 3 | B24: Utiliza un Glosario de términos normalizado? | D24: X
A25: 4 | B25: Los requerimientos Funcionales estan sujetos a una única interpretación? | C25: X
A26: 5 | B26: El modelo aplicado cumple con la sintaxis? | C26: X
A27: SUMATORIA: | C27: =COUNTA('MODELO LISTA DE COMPROBACIOCU10'!$C$22:$C$26) -> 4 | D27: =COUNTA('MODELO LISTA DE COMPROBACIOCU10'!$D$22:$D$26) -> 1
A28: PORCENTAJE : | C28: =C27/5 -> 0.8 | D28: =D27/5 -> 0.2
A30: NIVEL DE ACUERDO
A31: No. | B31: Pregunta | C31: SI | D31: NO
A32: 1 | B32: Todos los requerimientos han sido acordados con todos los interesados? | C32: X
A33: 2 | B33: Todos los requerimientos modificados han sido acordados por todos los implicados? | C33: X
A34: 3 | B34: Han sido resueltos todos los conflictos conocidos respectos de los requerimientos? | C34: X
A35: SUMATORIA: | C35: =COUNTA('MODELO LISTA DE COMPROBACIOCU10'!$C$32:$C$34) -> 3 | D35: =COUNTA('MODELO LISTA DE COMPROBACIOCU10'!$D$32:$D$34) -> 0
A36: PORCENTAJE : | C36: =C35/3 -> 1 | D36: =D35/3 -> 0
A40: RESUMEN
B41: CONTENIDO | C41: 56
B42: DOCUMENTACIÓN | C42: 100
B43: NIVEL DE ACUERDO | C43: 100

Sheet RECOMENDACIONES - CU001.1
A1: PREGUNTA | B1: RECOMENDACIÓN
A2: ¿Se han definido criterios de aceptación y casos de prueba que permitan verificar el cumplimiento del requisito? | B2: Diseñar y documentar casos de prueba específicos (ej. registro exitoso, error por producto duplicado) para que la funcionalidad pueda ser medida y validada antes de su aprobación.
A3: ¿Cuál es el plan de acción para que el requisito pase de estar estimado a estar construido? | B3: Iniciar la fase de desarrollo (programación) según el cronograma y presupuesto del proyecto, para validar técnicamente el caso de uso en el sistema.
A4: ¿Existe algún documento que permita vincular este requerimiento con sus orígenes y casos de prueba? | B4: Construir una Matriz de Trazabilidad global para el proyecto que enlace cada Caso de Uso con su código identificador, requerimiento del negocio y pruebas correspondientes.

Sheet RECOMENDACIONES - CU001.2
A1: PREGUNTA | B1: RECOMENDACIÓN
A2: ¿El catálogo de unidades de medida guarda coherencia con los módulos de productos, compras e inventario? | B2: Unificar los términos y asegurar que las unidades de medida creadas se integren correctamente en los formularios de registro de productos y compras. Incluir en el glosario definiciones claras para "unidad de medida", "abreviatura" y "estado" (activo/inactivo).
A3: ¿La descripción especifica sin ambigüedades la regla de eliminación y el uso de estados (activo/inactivo) para las unidades de medida? | B3: Clarificar si la eliminación es lógica (cambio de estado a inactivo) o física. Se recomienda aplicar inactivación para evitar romper la integridad referencial de los productos o compras históricas que ya tengan asignada dicha unidad.
A4: ¿Se han definido criterios de aceptación para controlar la duplicidad de nombres o abreviaturas y validar los campos requeridos? | B4: Elaborar criterios de aceptación en formato Given-When-Then (ej.: Dado un Administrador en el catálogo de unidades de medida, cuando intenta registrar una unidad con un nombre o abreviatura ya existente, el sistema bloquea el guardado y muestra un mensaje de error). Incluir casos de prueba para campos obligatorios y valores repetidos.
A5: ¿Se ha acotado la gestión del catálogo dentro del presupuesto y alcance previsto para el prototipo funcional? | B5: Delimitar las operaciones CRUD (Crear, Leer, Modificar, Inactivar) básicas dentro de la entrega inicial, difiriendo configuraciones complejas como factores de conversión entre unidades de medida si sobrepasan la estimación de esfuerzo.
A6: ¿Existe trazabilidad entre la gestión de unidades de medida y las entidades de datos de productos, compras y casos de prueba? | B6: Mapear en la matriz de trazabilidad la relación entre este caso de uso, los requerimientos funcionales de catálogo, el modelo de datos (tabla de unidades de medida) y las pantallas del módulo de productos y compras.

Sheet RECOMENDACIONES - CU001.3
A1: PREGUNTA | B1: RECOMENDACIÓN
A2: ¿Se han definido criterios de aceptación y casos de prueba que permitan verificar el cumplimiento del requisito? | B2: Elaborar y documentar casos de prueba específicos enfocados en la creación, modificación y eliminación de categorías para garantizar que la funcionalidad sea medible.
A3: ¿Cuál es el plan de acción para que el requisito pase de estar estimado a estar construido? | B3: Iniciar el desarrollo y programación del módulo de categorías según el cronograma del proyecto, para que la funcionalidad pueda ser validada en el sistema.
A4: ¿Existe algún documento que permita vincular este requerimiento con sus orígenes y casos de prueba? | B4: Integrar este requerimiento dentro de la Matriz de Trazabilidad del proyecto, vinculando el caso de uso con las necesidades del negocio y sus futuras pruebas.

Sheet RECOMENDACIONES - CU001.4
A1: PREGUNTA | B1: RECOMENDACIÓN
A2: ¿Se han validado y aprobado formalmente con el cliente y la docente las reglas del CU "Consolidar inventario del sistema"? | B2: Registrar en una minuta o acta la aceptación del cliente tras cada sesión de elicitación, adjuntarla al repositorio del proyecto y completar los campos de "Aprobación" del SRS (sección 1.3).
A3: ¿Está definido sin ambigüedad cómo se calculan las existencias consolidadas y quién dispara la consolidación? | B3: Documentar, acordada con el cliente, la regla de cálculo (cómo se combinan conteo físico y compras y de dónde se derivan las salidas por producto) y aclarar si la consolidación es automática o iniciada por el Administrador, usando un único criterio en Alcance, CU y RF-04.
A4: ¿Se han incorporado los cambios sugeridos en la revisión del SRS? | B4: Resolver las notas pendientes de la sección 1.1, unificar el nombre del proyecto (SIMP / BACAM_IMP) y alinear el nombre del CU entre diagrama y descripción, apoyándose en un registro de cambios por revisión.
A5: ¿Son coherentes entre sí el diagrama de casos de uso y la descripción del CU? | B5: Corregir el sentido de <<include>> (desde el caso base hacia el incluido), relacionar en el diagrama el registro de conteos físicos con la consolidación y representar al actor Sistema donde la descripción lo declara.
A6: ¿Se han definido criterios de aceptación y casos de prueba que permitan medir objetivamente el cumplimiento del requisito? | B6: Elaborar criterios de aceptación en formato Given-When-Then (p. ej.: dado un conteo físico y compras registradas de un producto, cuando el Administrador consolida, entonces las existencias y el detalle de entradas y salidas se actualizan), cada uno cubierto por al menos un caso de prueba; confirmar con el cliente si se requiere un tiempo máximo de respuesta.
A7: ¿Contiene el CU toda la información necesaria (precondiciones, postcondiciones, flujos) para entender y diseñar la función? | B7: Agregar precondiciones (usuario autenticado, conteos y compras registrados), postcondiciones, flujo principal y alternos; completar la descripción de RF-04, añadir un RF-UI para la pantalla de consolidación, incluir "Consolidación" en el glosario y asignar un ID explícito al CU.

Sheet RECOMENDACIONES - CU001.5
A1: PREGUNTA | B1: RECOMENDACIÓN
A2: ¿Se han definido criterios de aceptación y casos de prueba que permitan verificar el cumplimiento del requisito? | B2: Diseñar casos de prueba enfocados en los filtros de búsqueda (ej. búsqueda sin resultados, filtros por fecha o categoría) para asegurar que la visualización del stock sea medible.
A3: ¿Cuál es el plan de acción para que el requisito pase de estar estimado a estar construido? | B3: Iniciar el desarrollo de la interfaz de consultas de acuerdo con el cronograma del proyecto para validar su funcionamiento técnico real.
A4: ¿Existe algún documento que permita vincular este requerimiento con sus orígenes y pruebas? | B4: Incluir este requerimiento en la Matriz de Trazabilidad del proyecto, conectando la necesidad de consulta con sus respectivos casos de prueba.
A5: ¿La especificación del caso de uso detalla completamente los estados iniciales y finales del sistema? | B5: Actualizar la documentación del caso de uso agregando explícitamente las precondiciones (ej. el usuario debe estar autenticado) y las postcondiciones (ej. el sistema muestra la tabla actualizada).

Sheet RECOMENDACIONES - CU001.6
A1: PREGUNTA | B1: RECOMENDACIÓN
A2: ¿Se mantiene la coherencia con otros requisitos del sistema y utiliza término o definiciones de forma uniforme a lo largo del documento? | B2: Alinear la clasificación del CU con sus requisitos: RF-06 tiene prioridad Alta/Esencia, por lo que se debe revisar el tipo "Secundario y automático" o justificar la diferencia en el SRS. Además, unificar el nombre del CU entre el diagrama ("Actualizar existencias del sistema") y la descripción, apoyándose en un registro de cambios.
